Workbook

Sheet Input
A1: Assumptions
A2: Item | B2: Unit | C2: Amt | D2: Remarks
A3: Type of Agreement | D3: JDA - Revenue Sharing
A4: Land Area | C4: 13373.78
A5: Project Start Date | C5: 46174
A6: Project Period | B6: Yrs | C6: 4
A7: Starting Sale Price - Resi | B7: Rs/Sft | C7: 19500 | D7: On RERA Carpet
A8: Starting Sale Price - Comm/Retail | B8: Rs/Sft | C8: 30000 | D8: On RERA Carpet
A9: Car Park Price | B9: Rs/Unit | C9: 700000
A10: Club Membership Price | B10: Rs/Unit | C10: 200000
A11: Sales Growth % YOY | C11: 0.045
A14: Funds Required to Commence Project
A15: Item | B15: Cr
A16: Deposit to Landowner | B16: ='ANA Summary'!F48 -> 75
A17: Stamp Duty | B17: 8
A18: FSI/TDR purchase | B18: -
A19: Premiums & Approvals | B19: ='Approvals & Liasoning'!G22/10^7 -> 65.342451
A20: Total | B20: =SUM(B16:B19) -> 148.34245
A23: Standard Efficiency Ratios
A24: Item | B24: %
A25: FSI to RERA Carpet (Resi) | B25: 0.73
A26: FSI to RERA Carpet (Comm) | B26: 0.02
A27: Blended RERA Carpet Area to FSI | B27: ='FSI & Area Cal'!F50 -> 0.75

Sheet Output
A1: ANA Avant Garde - Phase II
A3: Total FSI | B3: ='FSI & Area Cal'!E47 -> 737285.61 | C3: sf
A4: Residential Carpet Area | B4: ='FSI & Area Cal'!E48 -> 538218.5 | C4: sf
A5: Retail/Commercial Carpet Area | B5: ='FSI & Area Cal'!E49 -> 14745.712 | C5: sf
A6: Revenue share of Landowner | B6: ='ANA Summary'!E46 -> 0.234
A7: Int Free Refundable Deposit to Landowner | B7: 75 | C7: Cr
A8: Particulars | B8: PSF (Carpet) | C8: Rs. Cr. | D8: %
A9: Net Revenues - Resi | B9: =IFERROR(C9*10^7/B4,0) -> 20780.076 | C9: ='Sales and Collection'!B14 -> 1118.4222 | D9: =C9/$C$12 -> 0.95929899
A10: Net Revenues - Retail/Comm | B10: =IFERROR(C10*10^7/B5,0) -> 32180.381 | C10: ='Sales and Collection'!B29 -> 47.452264 | D10: =C10/$C$12 -> 0.040701008
A11: Total Blended Rate | B11: =(C12*10^7)/(B4+B5) -> 21084.085
A12: Total Revenues (Inclusing Parking + CH) | C12: =SUM(C9:C10)+'Sales and Collection'!D40 -> 1165.8744 | D12: =C12/$C$12 -> 1
A13: Liason and approval cost | C13: ='Approvals & Liasoning'!G22/10^7 -> 65.342451 | D13: =C13/$C$12 -> 0.056045874
A14: Admin & Sales Overheads | C14: =D14*C12 -> 81.611209 | D14: =Output!C33 -> 0.07
A15: Interest & SD | C15: =SUM('ANA Summary'!F35:F36) -> 40 | D15: =C15/C12 -> 0.034309013
A16: Project Development Cost | C16: ='Detailed Costing'!E32 -> 304.56469 | D16: =C16/C12 -> 0.26123285
A17: Revenue share of Landowner | C17: =C12*B6 -> 272.81461 | D17: =C17/$C$12 -> 0.234
A18: Net Gains to Developer | C18: =C12-SUM(C13:C17) -> 401.54145 | D18: =C18/$C$12 -> 0.34441226
A20: Residential Launch Price (on carpet) | B20: =Input!C7 -> 19500 | C20: per sqft
A21: Retail / Comm Launch Price (on carpet) | B21: =Input!C8 -> 30000 | C21: per sqft
A24: Total Number of Units
A25: Number of Car Parks
A27: Average SP Residential | B27: Rs/Sft | C27: =IFERROR('Sales and Collection'!B14*10^7/'FSI & Area Cal'!E48,0) -> 20780.076 | D27: On RERA Carpet
A28: Average SP Comm/Retail | B28: Rs/Sft | C28: =IFERROR('Sales and Collection'!B29*10^7/'FSI & Area Cal'!E49,0) -> 32180.381 | D28: On RERA Carpet
A29: Blended Resi/Comm | B29: Rs/Sft | C29: =(('Sales and Collection'!B4+'Sales and Collection'!D40)*10^7)/('FSI & Area Cal'!E50) -> 21084.085 | D29: On RERA Carpet
A30: Cost of Construction over project lifecycle | B30: Rs/Sft | C30: ='Detailed Costing'!G32 -> 5507.8555 | D30: On RERA Carpet
A31: Cost Inflation YOY | C31: 0.035 | D31: On Construction Cost
A32: Project Interest Cost | C32: 32
A33: Sales , Marketing, Admin, and Overhead Cost | C33: 0.07 | D33: On Sales
A34: % of units with car park | C34: 0.65

Sheet ANA Summary
A1: TOD - Transit Oriented Development (Metro) (New DCR - Sec-14.2) | F1: Feasibility Model Summary
B3: IGR Data
A4: Sr. No. | B4: Project | C4: Registration Date | D4: RERA Carpet (Sft) | E4: Rate/Sft | F4: Amount | H4: Remarks
A5: 1 | B5: Jp North Aviva | C5: 45547 | D5: 263 | E5: =F5/D5 -> 22349.81 | F5: 5878000 | H5: Project launched July 2020
A6: 2 | B6: Jp North Aviva | C6: 45485 | D6: 263 | E6: =F6/D6 -> 21567.681 | F6: 5672300
A7: 3 | B7: Jp North Aviva | C7: 45282 | D7: 263 | E7: =F7/D7 -> 22343.156 | F7: 5876250
A8: 4 | B8: Jp North Aviva | C8: 45260 | D8: 263 | E8: =F8/D8 -> 23434.274 | F8: 6163214
A9: 5 | B9: Jp North Celeste | C9: 45467 | D9: 503 | E9: =F9/D9 -> 21868.787 | F9: 11000000
A10: 6 | B10: Sunteck Sky Park | C10: 45407 | D10: 652 | E10: =F10/D10 -> 20615.491 | F10: 13441300 | H10: First sale of project on 15 May 2023
A11: 7 | B11: Sunteck Sky Park | C11: 45394 | D11: 652 | E11: =F11/D11 -> 20507.822 | F11: 13371100
A12: 8 | B12: Sunteck Sky Park | C12: 45218 | D12: 936 | E12: =F12/D12 -> 20081.197 | F12: 18796000
A13: 9 | B13: Sunteck Sky Park | C13: 45215 | D13: 652 | E13: =F13/D13 -> 19269.632 | F13: 12563800
E15: =AVERAGE(E5:E14) -> 21337.539
B17: Revenue
B18: Revenue Heads | D18: Area/Nos | E18: Rate | F18: Amt | G18: On RERA
B19: FSI Potential | C19: ='FSI & Area Cal'!D47 -> 68495.505 | D19: ='FSI & Area Cal'!E47 -> 737285.61
A20: 1 | B20: Rev on Resi | C20: =D20/10.764 -> 50001.719 | D20: ='FSI & Area Cal'!E48 -> 538218.5 | E20: =Output!C27 -> 20780.076 | F20: =E20*D20/10^7 -> 1118.4222
A21: =A20+1 -> 2 | B21: Rev on Commercial | D21: ='FSI & Area Cal'!E49 -> 14745.712 | E21: =Output!C28 -> 32180.381 | F21: =E21*D21/10^7 -> 47.452264
A22: =A21+1 -> 3 | B22: Nos of Car Parks | C22: 0.65 | D22: 0 | E22: 0 | F22: =E22*D22/10^7 -> 0
A23: =A22+1 -> 4 | B23: Club House Chs | D23: =D22 -> 0 | E23: 0 | F23: =E23*D23/10^7 -> 0
A24: =A23+1 -> 5 | B24: Total Revenue | C24: =D24/D19 -> 0.75 | D24: ='FSI & Area Cal'!E50 -> 552964.21 | F24: =SUM(F20:F23) -> 1165.8744 | G24: =F24*10^7/$D$24 -> 21084.085
B26: Cost Details
B27: Cost Heads | C27: Unit | D27: Qty | E27: Rate | F27: Amt | H27: Remarks
A28: =A24+1 -> 6 | B28: Land Cost | F28: =E28*D28/10^7 -> 0
A29: =A28+1 -> 7 | B29: Liasioning Cost | F29: ='Approvals & Liasoning'!G22/10^7 -> 65.342451 | H29: Refer Stat & Premium Working sheet
A30: =A29+1 -> 8 | B30: Resi - Construction Cost (Incl GST) | C30: Sft | D30: ='FSI & Area Cal'!H63 -> 876783.78 | E30: ='Detailed Costing'!F27 -> 3121.3608 | F30: =E30*D30/10^7 -> 273.67585 | H30: Includes Parking area @1100Rs/Sft
A31: =A30+1 -> 9 | B31: Comm - Construction Cost (Incl GST) | C31: Sft | D31: ='FSI & Area Cal'!H64 -> 17866.984 | E31: ='Detailed Costing'!F28 -> 2450 | F31: =E31*D31/10^7 -> 4.3774111
A32: =A31+1 -> 10 | B32: Clubhouse COC | C32: Sft | D32: ='FSI & Area Cal'!H68 -> 8578.2406 | E32: ='Detailed Costing'!F29 -> 6000 | F32: =E32*D32/10^7 -> 5.1469444
A33: =A32+1 -> 11 | B33: Podium & Parking COC | C33: Sft | D33: ='FSI & Area Cal'!H67 -> 194222.6 | E33: ='Detailed Costing'!F30 -> 1100 | F33: =E33*D33/10^7 -> 21.364486
A34: =A33+1 -> 12 | B34: SM&OH | E34: 0.07 | F34: =F24*E34 -> 81.611209
A35: =A34+1 -> 13 | B35: INT | F35: =Output!C32 -> 32
A36: =A35+1 -> 14 | B36: SD | F36: =Input!B17 -> 8
B38: Total Cost | F38: =SUM(F28:F37) -> 491.51835 | G38: =F38*10^7/$D$24 -> 8888.7914
B40: Net Gains | F40: =F24-F38 -> 674.35606
B42: Net Gains to Developer | F42: =F47-F38 -> 401.54145
B43: Profit Before Tax (PBT) | F43: =F42/F24 -> 0.34441226
E45: On Rev Share | F45: =F24 -> 1165.8744
D46: LO | E46: 0.234 | F46: =F45*E46 -> 272.81461
D47: Dev | E47: =1-E46 -> 0.766 | F47: =F45*E47 -> 893.0598
D48: Deposit | F48: 75 | G48: Interest Free Refundable Deposit

Sheet FSI & Area Cal
A2: PROFORMA - I
A3: AREA STATEMENT - As per Architect Certificate
D4: Sqm | E4: Sft
A5: 1 | C5: Area of Plot (Minimum area of a, b, c to be considered)
B6: (a) | C6: As per ownership document (7/12, CTS extract) | D6: =Input!C4 -> 13373.78 | E6: =D6*10.764 -> 143955.37
B7: (b) | C7: As per measurement sheet
B8: (c) | C8: As per site
A9: 2 | C9: Deductions for
B10: (a) | C10: Proposed D.P./ D.P. Road widening Area/Service Road / Highway widening | D10: …
B11: (b) | C11: Any D.P. Reservation area | D11: …
B12: (c) | C12: Total (a+b) | D12: …
A13: 3 | C13: Balance area of plot (1-2) | D13: =D6 -> 13373.78 | E13: =D13*10.764 -> 143955.37
A14: 4 | C14: Amenity space (If applicable)
B15: (a) | C15: Required | D15: =5%*D6 -> 668.689 | E15: =D15*10.764 -> 7197.7684
B16: (b) | C16: Adjustment of 2(b), if any | D16: …
B17: (c) | C17: Balance proposed | D17: =D15 -> 668.689 | E17: =D17*10.764 -> 7197.7684
A18: 5 | C18: Net plot area (3-4(c)) | D18: =D13-D17 -> 12705.091 | E18: =D18*10.764 -> 136757.6
A19: 6 | C19: Recreational open space (If applicable)
B20: (a) | C20: Required | D20: =D18*0.1 -> 1270.5091 | E20: =D20*10.764 -> 13675.76
B21: (b) | C21: Proposed | D21: =D20 -> 1270.5091 | E21: =D21*10.764 -> 13675.76
A22: 7 | C22: Internal Road area | D22: …
A23: 8 | C23: Plotable area (If applicable) | D23: …
A24: 9 | C24: Built up area with reference to Basic F.S.I. as per front road width (Sr. No. 5 x basic FSI) (12704.78 x 1.10) | D24: =D18*1.1 -> 13975.6 | E24: =D24*10.764 -> 150433.36
A25: 10 | C25: Addition of FSI on payment of premium
B26: (a) | C26: Maximum permissible premium FSI - based on road width / TOD Zone (13373.78 x 2.9)-669.00 | D26: =(D6*2.9)-D17-D17 -> 37446.584 | E26: =D26*10.764 -> 403075.03
B27: (b) | C27: Proposed FSI on payment of premium. | D27: =D26 -> 37446.584 | E27: =D27*10.764 -> 403075.03
A28: 11 | C28: In-situ FSI / TDR loading
B29: (a) | C29: In-situ area against D.P. road [2.00x Sr. No. 2 (a)],if any | D29: …
B30: (b) | C30: In-situ area against Amenity Space if handed over [2.00 or1.85 x Sr. No. 4 (b)and /or(c)] | D30: =D15+D15 -> 1337.378 | E30: =D30*10.764 -> 14395.537
B31: (c) | C31: TDR Area (1730x 0.9)=1557-700=857 | D31: …
B32: (d) | C32: Total in-situ / TDR loading proposed (11 (a)+(b)+(c)) | D32: =D30 -> 1337.378 | E32: =D32*10.764 -> 14395.537
A33: 12 | C33: Additional FSI area under Chapter No. 7
A34: 13 | C34: Total entitlement of FSI in the proposal
B35: (a) | C35: [9 + 10(b)+11(d)] or 12 whichever is applicable. | D35: =D24+D27+D32 -> 52759.562 | E35: =D35*10.764 -> 567903.93
C36: Less Existing FSI (O.C. No: MNP/NR/5276/2019-20 dated 17/01/2020) | D36: 10737.78 | E36: =D36*10.764 -> 115581.46
C37: Balance FSI | D37: =D35-D36 -> 42021.782 | E37: =D37*10.764 -> 452322.46
C38: 0.15 | D38: =D37*C38 -> 6303.2673 | E38: =D38*10.764 -> 67848.369
C39: Balance Residential Area | D39: =D37-D38 -> 35718.515 | E39: =D39*10.764 -> 384474.09
B40: (b) | C40: Ancillary Area FSI with payment of charges.
C41: 0.6 | D41: =D39*C41 -> 21431.109 | E41: =D41*10.764 -> 230684.46
...

Sheet Detailed Costing
A1: Cost Breakup
A2: Itemised Rate
A3: All costs are including GST
D4: Construction Area | G4: RERA Carpet Area
A5: FSI Potential | D5: ='FSI & Area Cal'!E47 -> 737285.61 | G5: ='FSI & Area Cal'!E51 -> 552964.21
A6: Resi Construction Area | D6: ='FSI & Area Cal'!H63 -> 876783.78 | G6: ='FSI & Area Cal'!E48 -> 538218.5
A7: Comm Construction Area | D7: ='FSI & Area Cal'!H64 -> 17866.984 | G7: ='FSI & Area Cal'!E49 -> 14745.712
A8: Resi+Comm Construction Area | D8: ='FSI & Area Cal'!H65 -> 894650.77
A9: Club House Area | D9: ='FSI & Area Cal'!H68 -> 8578.2406
A10: Podium & Parking Area | D10: ='FSI & Area Cal'!H67 -> 194222.6
A11: Total Construction Area | D11: =SUM(D8:D10) -> 1097451.6 | E11: =D11/G5 -> 1.9846702 | G11: =SUM(G6:G10) -> 552964.21
A12: Item | B12: Unit | C12: Qty | D12: Rate - % | E12: Amount | F12: Rs/Sft - On Con Area | G12: Rs/Sft - On RERA Carpet
A13: Excavation & Soiling | B13: Sft | C13: =D6 -> 876783.78 | E13: =C13*F13/10^7 -> 1.402854 | F13: 16 | G13: =E13*10^7/$G$6 -> 26.064768
A14: RCC, Block Work, Plaster, Water Proofing | B14: Sft | C14: =C13 -> 876783.78 | E14: =C14*F14/10^7 -> 141.33755 | F14: 1612 | G14: =E14*10^7/$G$6 -> 2626.0254
A15: Finishes (Flooring, Doors, Windows, Painting) | B15: Sft | C15: =C14 -> 876783.78 | E15: =C15*F15/10^7 -> 56.990946 | F15: 650 | G15: =E15*10^7/$G$6 -> 1058.8812
A16: MEP (Plumbing, sanitary, electricals, FF, Lifts) | B16: Sft | C16: =C15 -> 876783.78 | E16: =C16*F16/10^7 -> 43.839189 | F16: 500 | G16: =E16*10^7/$G$6 -> 814.52401
A17: Sub-total Tower Cost | E17: =SUM(E13:E16) -> 243.57053 | F17: =SUM(F13:F16) -> 2778 | G17: =SUM(G13:G16) -> 4525.4954
A18: Infrastructure | D18: 0.04 | E18: =D18*E17 -> 9.7428214 | F18: =D18*F17 -> 111.12 | G18: =E18*10^7/$G$6 -> 181.01982
A19: Preliminary and Miscellaneous Costs | D19: 0.02 | E19: =D19*E17 -> 4.8714107 | F19: =D19*F17 -> 55.56 | G19: =E19*10^7/$G$6 -> 90.509908
A20: Sub-total Construction Cost | E20: =E17+SUM(E18:E19) -> 258.18477 | F20: =F17+SUM(F18:F19) -> 2944.68 | G20: =G17+SUM(G18:G19) -> 4797.0251
A21: Consultants | B21: Sft | C21: =D11 -> 1097451.6 | D21: 0.04 | E21: =C21*F21/10^7 -> 12.926575 | F21: =D21*$F$20 -> 117.7872 | G21: =E21*10^7/$G$6 -> 240.17337
A22: Approvals | D22: 0 | E22: 0 | F22: =D22*$F$20 -> 0 | G22: =E22*10^7/$G$6 -> 0
A23: Admin & Overheads | D23: 0 | E23: 0 | F23: =D23*$F$20 -> 0 | G23: =E23*10^7/$G$6 -> 0
A24: Contingency | B24: Sft | C24: =C21 -> 1097451.6 | D24: 0.02 | E24: =C24*F24/10^7 -> 6.4632876 | F24: =D24*$F$20 -> 58.8936 | G24: =E24*10^7/$G$6 -> 120.08669
A25: Sub-total | E25: =SUM(E21:E24) -> 19.389863 | F25: =SUM(F21:F24) -> 176.6808 | G25: =SUM(G21:G24) -> 360.26006
A27: Total Resi Construction Cost | B27: Sft | C27: =D6 -> 876783.78 | E27: =F27*C27/10^7 -> 273.67585 | F27: =F20+F25 -> 3121.3608 | G27: =E27*10^7/$G$6 -> 5084.8466
A28: Total Comm Construction Cost | B28: Sft | C28: =D7 -> 17866.984 | E28: =F28*D7/10^7 -> 4.3774111 | F28: 2450 | G28: =E28*10^7/G7 -> 2968.5993
A29: Club House | B29: Sft | C29: =D9 -> 8578.2406 | E29: =F29*D9/10^7 -> 5.1469444 | F29: 6000 | G29: =E29*10^7/$G$11 -> 93.079159
A30: Parking Levels | B30: Sft | C30: =D10 -> 194222.6 | E30: =F30*D10/10^7 -> 21.364486 | F30: 1100 | G30: =E30*10^7/$G$11 -> 386.36291
A32: Total | B32: Sft | C32: =D11 -> 1097451.6 | E32: =SUM(E27:E30) -> 304.56469 | F32: =E32*10^7/C32 -> 2775.1993 | G32: =E32*10^7/$G$11 -> 5507.8555

Sheet Approvals & Liasoning
A1: ANA Avant Garde - Phase II - Statutory Expenses & Premium Charges
A3: Sr | B3: Title | C3: Ref No | D3: Unit | E3: Qty | F3: Rate | G3: Amount | H3: Remarks
A4: 1 | B4: Scrutiny Charges | C4: A
B5: On Plot Area @ Rs. 2000/Acre | D5: Acre | E5: =13373.78/4046.86 -> 3.3047301 | F5: 2000 | G5: =E5*F5 -> 6609.4602 | H5: Gross Plot Area(13373.78 SqM)/4046.86 x Rs. 2000/-
B6: On B/up Area (5/SqMt) | D6: SqM | E6: 68495.5 | F6: 5 | G6: =E6*F6 -> 342477.5 | H6: BUA = Balance Permissible FSI/Potential in project
A7: 2 | B7: Development Charges | C7: B
B8: On Plot Area (0.5% of RR) 31600 RR | D8: SqM | E8: 13373.78 | F8: 0.005 | G8: =E8*31600*F8 -> 2113057.2 | H8: Reckoner Rate = 31600 / SqM
B9: On Resi B/up area (2% of RR) 31600 RR | D9: SqM | E9: 62434.304 | F9: 0.02 | G9: =E9*31600*F9 -> 39458480 | H9: Reckoner Rate = 31600 / SqM
B10: On Comm B/up area (4% of RR) 31600 RR | D10: SqM | E10: 5400 | F10: 0.04 | G10: =E10*31600*F10 -> 6825600 | H10: Reckoner Rate = 31600 / SqM
A11: 3 | B11: Vital Transport Project Development Charges
B12: @100% Development Charges | C12: C=Sum of B | G12: =SUM(G8:G11)*1 -> 48397137 | H12: Metro Charges (Newly Introduced)
A13: 4 | B13: Premium FSI Charges
B14: On Total FSI (Less TDR) - (@35% of RR) 31600 RR | C14: D | D14: SqM | E14: 37446.58 | F14: 0.35 | G14: =E14*31600*F14 -> 4.1415917e+08 | H14: Total FSI = 38783.96 Sqm - Less Amenity 669 SqM
B15: TDR Amount | C15: E | D15: SqM | E15: 0 | G15: 0
B16: Ancillary FSI - (@10% of RR) 31600 RR | C16: F | D16: SqM | E16: 26473.72 | F16: 0.1 | G16: =E16*31600*F16 -> 83656955 | H16: Total of Both Ancillary Proposed
A17: 5 | B17: Labour Cess - (@1% of RR construction on Gross BUA) 26620 | C17: G | D17: SqM | E17: =(E6)+(E6*0.3) -> 89044.15 | F17: 0.01 | G17: =E17*F17*26620 -> 23703553 | H17: Gross BUA = Permissible FSI + 30% of Permissible FSI (Towards Basement)
A18: 6 | B18: Construction Cess- @15/- on Gross BUA | C18: H | D18: SqM | E18: =E17 -> 89044.15 | F18: 15 | G18: =E18*F18 -> 1335662.2
A19: 7 | B19: Security Deposit @20/- on FSI BUA | C19: I | D19: SqM | E19: =E6 -> 68495.5 | F19: 20 | G19: =E19*F19 -> 1369910
A20: 8 | B20: Property Tax Deposit @210/- on Gross BUA | C20: J | D20: SqM | E20: =E17 -> 89044.15 | F20: 210 | G20: =E20*F20 -> 18699272
A21: 9 | B21: Fire Premium @150 Per Sq.Mt. on Gross B/up | C21: K | D21: SqM | E21: =E20 -> 89044.15 | F21: 150 | G21: =E21*F21 -> 13356622
B22: Total | G22: =SUM(G5:G21) -> 6.5342451e+08

Sheet Sales and Collection
A2: QY End | D2: =Input!C5 -> 46174 | E2: =EOMONTH(D2,3) -> 46295 | F2: =EOMONTH(E2,3) -> 46387 | G2: =EOMONTH(F2,3) -> 46477 | H2: =EOMONTH(G2,3) -> 46568 | I2: =EOMONTH(H2,3) -> 46660 | J2: =EOMONTH(I2,3) -> 46752 | K2: =EOMONTH(J2,3) -> 46843 | L2: =EOMONTH(K2,3) -> 46934 | ... T2: =EOMONTH(S2,3) -> 47664
A3: FY End | D3: =IF(MONTH(D2)>3,DATE(YEAR(D2)+1,3,31),D2) -> 46477 | E3: =IF(MONTH(E2)>3,DATE(YEAR(E2)+1,3,31),E2) -> 46477 | F3: =IF(MONTH(F2)>3,DATE(YEAR(F2)+1,3,31),F2) -> 46477 | G3: =IF(MONTH(G2)>3,DATE(YEAR(G2)+1,3,31),G2) -> 46477 | H3: =IF(MONTH(H2)>3,DATE(YEAR(H2)+1,3,31),H2) -> 46843 | I3: =IF(MONTH(I2)>3,DATE(YEAR(I2)+1,3,31),I2) -> 46843 | J3: =IF(MONTH(J2)>3,DATE(YEAR(J2)+1,3,31),J2) -> 46843 | K3: =IF(MONTH(K2)>3,DATE(YEAR(K2)+1,3,31),K2) -> 46843 | ... T3: =IF(MONTH(T2)>3,DATE(YEAR(T2)+1,3,31),T2) -> 47938
A4: Total Sales (INR in Crores) | B4: =SUM(D4:T4) -> 1165.8744 | D4: =D14+D26 -> 0 | E4: =E14+E26 -> 209.90521 | F4: =F14+F26 -> 108.10119 | G4: =G14+G26 -> 116.94861 | H4: =H14+H26 -> 88.064591 | I4: =I14+I26 -> 88.064591 | J4: =J14+J26 -> 89.533249 | K4: =K14+K26 -> 89.533249 | ... T4: =T14+T26 -> 33.621772
A5: Total Collection (INR in Crores) | B5: =SUM(D5:T5) -> 1165.8744 | D5: =D17+D29 -> 0 | E5: =E17+E29 -> 20.990521 | F5: =F17+F29 -> 26.710439 | G5: =G17+G29 -> 38.4053 | H5: =H17+H29 -> 68.789043 | I5: =I17+I29 -> 85.946319 | J5: =J17+J29 -> 71.21421 | K5: =K17+K29 -> 80.519519 | ... T5: =T17+T29 -> 33.621772
A6: Construction schedule | B6: =SUM(D6:T6) -> 1 | D6: =D19 -> 0 | E6: =E19 -> 0.03 | F6: =F19 -> 0.05 | G6: =G19 -> 0.05 | H6: =H19 -> 0.05 | I6: =I19 -> 0.05 | J6: =J19 -> 0.05 | K6: =K19 -> 0.05 | ... T6: =T19 -> 0
A7: Construction Cost Outflow (Cr) | D7: =(D31*('Detailed Costing'!$E$32*10^7))/10^7 -> 0 | E7: =(E31*('Detailed Costing'!$E$32*10^7))/10^7 -> 9.1369408 | F7: =(F31*('Detailed Costing'!$E$32*10^7))/10^7 -> 15.228235 | G7: =(G31*('Detailed Costing'!$E$32*10^7))/10^7 -> 15.228235 | H7: =(H31*('Detailed Costing'!$E$32*10^7))/10^7 -> 15.228235 | I7: =(I31*('Detailed Costing'!$E$32*10^7))/10^7 -> 15.228235 | J7: =(J31*('Detailed Costing'!$E$32*10^7))/10^7 -> 15.228235 | K7: =(K31*('Detailed Costing'!$E$32*10^7))/10^7 -> 15.228235 | ... T7: =(T31*('Detailed Costing'!$E$32*10^7))/10^7 -> 0
A9: Resi. - Phase I (area sf) | B9: ='FSI & Area Cal'!E48 -> 538218.5 | R9: =R10/Q10-1 -> 0
A10: Selling price psf | B10: =Output!B20 -> 19500 | D10: 0 | E10: =B10 -> 19500 | F10: =E10*1.03 -> 20085 | G10: =F10 -> 20085 | H10: =G10*1.03 -> 20687.55 | I10: =H10 -> 20687.55 | J10: =I10*1.03 -> 21308.177 | K10: =J10 -> 21308.177 | L10: =K10 -> 21308.177 | M10: =L10*1.03 -> 21947.422 | N10: =M10 -> 21947.422 | O10: =N10 -> 21947.422 | P10: =O10 -> 21947.422 | Q10: =P10 -> 21947.422 | R10: =Q10 -> 21947.422 | S10: =R10 -> 21947.422 | T10: =S10*1.05 -> 23044.793
A12: Sales phasing | B12: =B9 -> 538218.5 | D12: 0 | E12: 0.2 | F12: 0.1 | G12: 0.1 | H12: 0.075 | I12: 0.075 | J12: 0.075 | K12: 0.075 | L12: 0.075 | M12: 0.05 | N12: 0.025 | O12: 0.025 | P12: 0.025 | Q12: 0.025 | R12: 0.025 | S12: 0.025 | T12: 0.025
A13: Area sold (sf) | B13: =SUM(D13:FH13) -> 538218.5 | D13: =$B$12*D12 -> 0 | E13: =$B$12*E12 -> 107643.7 | F13: =$B$12*F12 -> 53821.85 | G13: =$B$12*G12 -> 53821.85 | H13: =$B$12*H12 -> 40366.387 | I13: =$B$12*I12 -> 40366.387 | J13: =$B$12*J12 -> 40366.387 | K13: =$B$12*K12 -> 40366.387 | ... T13: =$B$12*T12 -> 13455.462
A14: Sales value (INR Cr) | B14: =SUM(D14:FH14) -> 1118.4222 | D14: =D13*D10/10^7 -> 0 | E14: =E13*E10/10^7 -> 209.90521 | F14: =F13*F10/10^7 -> 108.10119 | G14: =G13*G10/10^7 -> 108.10119 | H14: =H13*H10/10^7 -> 83.508166 | I14: =I13*I10/10^7 -> 83.508166 | J14: =J13*J10/10^7 -> 86.013411 | K14: =K13*K10/10^7 -> 86.013411 | ... T14: =T13*T10/10^7 -> 31.007835
A16: Cumulative collection phasing | D16: 0 | E16: 0.1 | F16: 0.15 | G16: 0.2 | H16: 0.3 | I16: 0.4 | J16: 0.45 | K16: 0.5 | L16: 0.6 | M16: 0.65 | N16: 0.7 | O16: 0.8 | P16: 0.9 | Q16: 0.95 | R16: 1 | S16: 1 | T16: 1
A17: Incremental collections (INR Cr) | B17: =SUM(D17:FH17) -> 1118.4222 | D17: =SUM(D14:$D$15)*D16 -> 0 | E17: =SUM($D14:E$14)*E16-SUM($D17:D$17) -> 20.990521 | F17: =SUM($D14:F$14)*F16-SUM($D17:E$17) -> 26.710439 | G17: =SUM($D14:G$14)*G16-SUM($D17:F$17) -> 37.520557 | H17: =SUM($D14:H$14)*H16-SUM($D17:G$17) -> 67.663208 | I17: =SUM($D14:I$14)*I16-SUM($D17:H$17) -> 84.364841 | J17: =SUM($D14:J$14)*J16-SUM($D17:I$17) -> 68.362231 | K17: =SUM($D14:K$14)*K16-SUM($D17:J$17) -> 76.963572 | L17: =SUM($D14:L$14)*L16-SUM($D17:K$17) -> 128.12312 | ... T17: =SUM($D14:T$14)*T16-SUM($D17:S$17) -> 31.007835
A19: Construction phasing | D19: 0 | E19: 0.03 | F19: 0.05 | G19: 0.05 | H19: 0.05 | I19: 0.05 | J19: 0.05 | K19: 0.05 | L19: 0.05 | M19: 0.05 | N19: 0.12 | O19: 0.12 | P19: 0.12 | Q19: 0.12 | R19: 0.07 | S19: 0.02 | T19: 0
A21: Comm. - Phase I (area sf) | B21: ='FSI & Area Cal'!E49 -> 14745.712 | R21: =R22/Q22-1 -> 0
A22: Selling price psf | B22: =Output!B21 -> 30000 | D22: 0 | E22: 0 | F22: 0 | G22: =B22 -> 30000 | H22: =G22*1.03 -> 30900 | I22: =H22 -> 30900 | J22: =I22*1.03 -> 31827 | K22: =J22 -> 31827 | L22: =K22*1.03 -> 32781.81 | M22: =L22 -> 32781.81 | N22: =M22 -> 32781.81 | O22: =N22*1.03 -> 33765.264 | P22: =O22 -> 33765.264 | Q22: =P22*1.05 -> 35453.528 | R22: =Q22 -> 35453.528 | S22: =R22 -> 35453.528 | T22: =S22 -> 35453.528
A24: Sales phasing | B24: =B21 -> 14745.712 | D24: 0 | E24: 0 | F24: 0 | G24: 0.2 | H24: 0.1 | I24: 0.1 | J24: 0.075 | K24: 0.075 | L24: 0.075 | M24: 0.075 | N24: 0.075 | O24: 0.05 | P24: 0.025 | Q24: 0.025 | R24: 0.025 | S24: 0.05 | T24: 0.05
A25: Area sold (sf) | B25: =SUM(D25:FH25) -> 14745.712 | D25: =$B$24*D24 -> 0 | E25: =$B$24*E24 -> 0 | F25: =$B$24*F24 -> 0 | G25: =$B$24*G24 -> 2949.1425 | H25: =$B$24*H24 -> 1474.5712 | I25: =$B$24*I24 -> 1474.5712 | J25: =$B$24*J24 -> 1105.9284 | K25: =$B$24*K24 -> 1105.9284 | ... T25: =$B$24*T24 -> 737.28561
A26: Sales value (INR Cr) | B26: =SUM(D26:FH26) -> 47.452264 | D26: =D25*D22/10^7 -> 0 | E26: =E25*E22/10^7 -> 0 | F26: =F25*F22/10^7 -> 0 | G26: =G25*G22/10^7 -> 8.8474274 | H26: =H25*H22/10^7 -> 4.5564251 | I26: =I25*I22/10^7 -> 4.5564251 | J26: =J25*J22/10^7 -> 3.5198384 | K26: =K25*K22/10^7 -> 3.5198384 | ... T26: =T25*T22/10^7 -> 2.6139376
A28: Cumulative collection phasing | D28: 0 | E28: 0 | F28: 0 | G28: 0.1 | H28: 0.15 | I28: 0.2 | J28: 0.3 | K28: 0.4 | L28: 0.5 | M28: 0.6 | N28: 0.6 | O28: 0.7 | P28: 0.9 | Q28: 0.95 | R28: 1 | S28: 1 | T28: 1
A29: Incremental collections (INR Cr) | B29: =SUM(D29:FH29) -> 47.452264 | D29: =SUM(D$26:$D26)*D28 -> 0 | E29: =SUM($D$26:E26)*E28-SUM($D$29:D29) -> 0 | F29: =SUM($D$26:F26)*F28-SUM($D$29:E29) -> 0 | G29: =SUM($D$26:G26)*G28-SUM($D$29:F29) -> 0.88474274 | H29: =SUM($D$26:H26)*H28-SUM($D$29:G29) -> 1.1258351 | I29: =SUM($D$26:I26)*I28-SUM($D$29:H29) -> 1.5814776 | J29: =SUM($D$26:J26)*J28-SUM($D$29:I29) -> 2.8519793 | K29: =SUM($D$26:K26)*K28-SUM($D$29:J29) -> 3.5559469 | L29: =SUM($D$26:L26)*L28-SUM($D$29:K29) -> 4.3127122 | ... T29: =SUM($D$26:T26)*T28-SUM($D$29:S29) -> 2.6139376
A31: Construction phasing | D31: 0 | E31: 0.03 | F31: 0.05 | G31: 0.05 | H31: 0.05 | I31: 0.05 | J31: 0.05 | K31: 0.05 | L31: 0.05 | M31: 0.05 | N31: 0.12 | O31: 0.12 | P31: 0.12 | Q31: 0.12 | R31: 0.07 | S31: 0.02 | T31: 0
A35: Car Park & CH Revenue
A36: Item | B36: Qty | D36: Amt
A37: Number of Units | B37: =Output!C24 -> 0
A38: Car Park Charge/Unit | C38: =Input!C9 -> 700000 | D38: =C38*B38/10^7 -> 0
A39: Clubhouse Charge/Unit | C39: =Input!C10 -> 200000 | D39: =C39*B39/10^7 -> 0
A40: Total Parking + CH Revenue | D40: =SUM(D38:D39) -> 0

Sheet Sales Phasing
A1: Sales Phasing
A2: Year 1 | B2: Q1 | C2: 0.2 | D2: 0.14
B3: Q2 | C3: 0.1
B4: Q3 | C4: 0.1
B5: Q4 | C5: 0.075
A6: Year 2 | B6: Q1 | C6: 0.075 | D6: 0.23
B7: Q2 | C7: 0.075
B8: Q3 | C8: 0.075
B9: Q4 | C9: 0.075
A10: Year 3 | B10: Q1 | C10: 0.05 | D10: 0.31
B11: Q2 | C11: 0.025
B12: Q3 | C12: 0.025
B13: Q4 | C13: 0.025
A14: Year 4 | B14: Q1 | C14: 0.025 | D14: 0.32
B15: Q2 | C15: 0.025
B18: Q3 | C18: 0.025
B19: Q4 | C19: 0.025
B20: TOTAL | C20: 1 | D20: 1

Sheet Cash Flow
A1: Project IRR | C1: 0.15
A3: Total Project CF
E4: Y1 | F4: Y2 | G4: Y3 | H4: Y4
A5: Sales Phasing | E5: ='Sales Phasing'!D2 -> 0.14 | F5: ='Sales Phasing'!D6 -> 0.23 | G5: ='Sales Phasing'!D10 -> 0.31 | H5: ='Sales Phasing'!D14 -> 0.32
A6: Construction Phasing | E6: =SUM('Sales and Collection'!E19:H19) -> 0.18 | F6: =SUM('Sales and Collection'!I19:L19) -> 0.2 | G6: =SUM('Sales and Collection'!M19:P19) -> 0.41 | H6: =SUM('Sales and Collection'!Q19:T19) -> 0.21
A7: Total Project Inflow | C7: ='ANA Summary'!F24 -> 1165.8744 | E7: =$C$7*E5 -> 163.22242 | F7: =$C$7*F5 -> 268.15112 | G7: =$C$7*G5 -> 361.42107 | H7: =$C$7*H5 -> 373.07981
A8: Prpject NPV | B8: ='Cash Flow'!C1 -> 0.15 | C8: =NPV(B8,E7:H7) -> 795.64312
A11: Developer Cashflow | I11: Total
E12: Y1 | F12: Y2 | G12: Y3 | H12: Y4
A13: DO Inflow CF | C13: ='ANA Summary'!F42 -> 401.54145 | E13: =$C$13*E5 -> 56.215803 | F13: =$C$13*F5 -> 92.354533 | G13: =$C$13*G5 -> 124.47785 | H13: =$C$13*H5 -> 128.49326 | I13: =SUM(E13:H13) -> 401.54145
A14: Project Initiaiton Expense | C14: =Input!B20 -> 148.34245 | E14: =-Input!B20 -> -148.34245 | I14: =SUM(E14:H14) -> -148.34245
A15: Refund on Deposit | C15: ='ANA Summary'!F48 -> 75 | E15: =-E28 -> 10.5 | F15: =-F28 -> 17.25 | G15: =-G28 -> 23.25 | H15: =-H28 -> 24 | I15: =SUM(E15:H15) -> 75
A16: Construction CF | C16: ='Detailed Costing'!E32 -> 304.56469 | E16: =-$C$16*E6 -> -54.821645 | F16: =-$C$16*F6 -> -60.912939 | G16: =-$C$16*G6 -> -124.87152 | H16: =-$C$16*H6 -> -63.958586 | I16: =SUM(E16:H16) -> -304.56469
A17: Sales CF | C17: ='ANA Summary'!F34 -> 81.611209 | E17: =-$C$17*E5 -> -11.425569 | F17: =-$C$17*F5 -> -18.770578 | G17: =-$C$17*G5 -> -25.299475 | H17: =-$C$17*H5 -> -26.115587 | I17: =SUM(E17:H17) -> -81.611209
A18: Landowner CF | B18: ='ANA Summary'!E46 -> 0.234 | E18: =-E7*$B$18 -> -38.194046 | F18: =-F7*$B$18 -> -62.747361 | G18: =-G7*$B$18 -> -84.57253 | H18: =-H7*$B$18 -> -87.300676 | I18: =SUM(E18:H18) -> -272.81461
A19: Developer Net Cashflow (Excl Int) | C19: =I19 -> 433.54145 | E19: =E7+SUM(E14:E18) -> -79.061293 | F19: =F7+SUM(F14:F18) -> 142.97024 | G19: =G7+SUM(G14:G18) -> 149.92754 | H19: =H7+SUM(H14:H18) -> 219.70496 | I19: =SUM(E19:H19) -> 433.54145
A20: Developer PBT | C20: =C13/C7 -> 0.34441226
A21: Landowner NPV | B21: ='Cash Flow'!C1 -> 0.15 | C21: =NPV(B21,E19:H19) -> 263.55391
A24: Landowner Cashflow | I24: Total
E25: Y1 | F25: Y2 | G25: Y3 | H25: Y4
A26: Rev Share CF | B26: ='ANA Summary'!E46 -> 0.234 | E26: =$B$26*E7 -> 38.194046 | F26: =$B$26*F7 -> 62.747361 | G26: =$B$26*G7 -> 84.57253 | H26: =$B$26*H7 -> 87.300676 | I26: =SUM(E26:H26) -> 272.81461
A27: Deposit Inflow | E27: ='ANA Summary'!F48 -> 75 | I27: =SUM(E27:H27) -> 75
A28: Deposit Adjustment | B28: =E27/I26 -> 0.27491196 | E28: =-E26*$B$28 -> -10.5 | F28: =-F26*$B$28 -> -17.25 | G28: =-G26*$B$28 -> -23.25 | H28: =-H26*$B$28 -> -24 | I28: =SUM(E28:H28) -> -75
A29: LO Net Cashflow | C29: =I29 -> 272.81461 | E29: =SUM(E26:E28) -> 102.69405 | F29: =SUM(F26:F28) -> 45.497361 | G29: =SUM(G26:G28) -> 61.32253 | H29: =SUM(H26:H28) -> 63.300676 | I29: =SUM(E29:H29) -> 272.81461
A30: Landowner NPV | B30: ='Cash Flow'!C1 -> 0.15 | C30: =NPV(B30,E29:H29) -> 200.21464

Sheet Project Config
